2024-03-15 12:34:57,878 — main.py:63 -     get_qna_response() — INFO — [] - answer_id:55497a10-e29a-11ee-8da7-acde48001122
2024-03-15 12:34:57,878 — main.py:66 -     get_qna_response() — INFO — [] - Starting to serve request:answer_id:55497a10-e29a-11ee-8da7-acde48001122
2024-03-15 12:44:16,315 — answer_generator.py:66 -             generate() — INFO — [] - answer_id:55497a10-e29a-11ee-8da7-acde48001122: time taken to generate result : 558.4369421005249 : 
2024-03-15 12:44:16,351 — main.py:122 -     get_qna_response() — ERROR — [] - InternalError: Object of type Response is not JSON serializable :Traceback (most recent call last):;  File "/Users/reverma/git/custom-rag-pipeline/src/main.py", line 90, in get_qna_response;    return Response(qa_gen.generate());  File "/Users/reverma/git/custom-rag-pipeline/src/answer_generator.py", line 70, in generate;    json_string = json.dumps(;  File "/Users/reverma/anaconda3/envs/test_gr/lib/python3.8/json/__init__.py", line 234, in dumps;    return cls(;  File "/Users/reverma/anaconda3/envs/test_gr/lib/python3.8/json/encoder.py", line 199, in encode;    chunks = self.iterencode(o, _one_shot=True);  File "/Users/reverma/anaconda3/envs/test_gr/lib/python3.8/json/encoder.py", line 257, in iterencode;    return _iterencode(o, 0);  File "/Users/reverma/anaconda3/envs/test_gr/lib/python3.8/json/encoder.py", line 179, in default;    raise TypeError(f'Object of type {o.__class__.__name__} ';TypeError: Object of type Response is not JSON serializable;
2024-03-15 12:44:48,265 — main.py:63 -     get_qna_response() — INFO — [] - answer_id:b52f5c96-e29b-11ee-8da7-acde48001122
2024-03-15 12:44:48,265 — main.py:66 -     get_qna_response() — INFO — [] - Starting to serve request:answer_id:b52f5c96-e29b-11ee-8da7-acde48001122
2024-03-15 13:16:08,912 — answer_generator.py:66 -             generate() — INFO — [] - answer_id:b52f5c96-e29b-11ee-8da7-acde48001122: time taken to generate result : 1880.646833896637 : 
2024-03-15 13:16:17,624 — main.py:122 -     get_qna_response() — ERROR — [] - InternalError: Object of type Response is not JSON serializable :Traceback (most recent call last):;  File "/Users/reverma/git/custom-rag-pipeline/src/main.py", line 90, in get_qna_response;    return Response(qa_gen.generate());  File "/Users/reverma/git/custom-rag-pipeline/src/answer_generator.py", line 70, in generate;    json_string = json.dumps(;  File "/Users/reverma/anaconda3/envs/test_gr/lib/python3.8/json/__init__.py", line 234, in dumps;    return cls(;  File "/Users/reverma/anaconda3/envs/test_gr/lib/python3.8/json/encoder.py", line 199, in encode;    chunks = self.iterencode(o, _one_shot=True);  File "/Users/reverma/anaconda3/envs/test_gr/lib/python3.8/json/encoder.py", line 257, in iterencode;    return _iterencode(o, 0);  File "/Users/reverma/anaconda3/envs/test_gr/lib/python3.8/json/encoder.py", line 179, in default;    raise TypeError(f'Object of type {o.__class__.__name__} ';TypeError: Object of type Response is not JSON serializable;
2024-03-15 13:22:28,563 — main.py:63 -     get_qna_response() — INFO — [] - answer_id:f86d6ba6-e2a0-11ee-9a6d-acde48001122
2024-03-15 13:22:28,563 — main.py:66 -     get_qna_response() — INFO — [] - Starting to serve request:answer_id:f86d6ba6-e2a0-11ee-9a6d-acde48001122
2024-03-15 14:16:43,674 — answer_generator.py:66 -             generate() — INFO — [] - answer_id:f86d6ba6-e2a0-11ee-9a6d-acde48001122: time taken to generate result : 3255.1111500263214 : 
2024-03-15 15:01:38,299 — main.py:70 -     get_qna_response() — INFO — [] - answer_id:d2bf15f4-e2ae-11ee-8eca-acde48001122
2024-03-15 15:01:38,299 — main.py:73 -     get_qna_response() — INFO — [] - Starting to serve request:answer_id:d2bf15f4-e2ae-11ee-8eca-acde48001122
2024-03-15 15:01:38,299 — main.py:54 -     validate_request() — WARNING — [] - answer_id:None:Defaulting Model
2024-03-15 15:01:38,308 — main.py:115 -     get_qna_response() — ERROR — [] - answer_id:d2bf15f4-e2ae-11ee-8eca-acde48001122:CustomException: 500 - Issue in initialising doc_retriever: DOC_RETRIEVER value <src.components.doc_retriever.VectorDBRetriever object at 0x7fba1818edf0> in config is invalid :Traceback (most recent call last):;  File "/Users/reverma/git/custom-rag-pipeline/src/main.py", line 94, in get_qna_response;    qa_gen.prepare();  File "/Users/reverma/git/custom-rag-pipeline/src/answer_generator.py", line 33, in prepare;    "user_query": user_query,;  File "/Users/reverma/git/custom-rag-pipeline/src/components/search_handler.py", line 22, in get_doc_retriever;    raise CustomException(;src.utils.exceptions.CustomException: CustomException: 500 - Issue in initialising doc_retriever: DOC_RETRIEVER value <src.components.doc_retriever.VectorDBRetriever object at 0x7fba1818edf0> in config is invalid;
2024-03-15 15:02:06,130 — main.py:70 -     get_qna_response() — INFO — [] - answer_id:e355ca70-e2ae-11ee-8eca-acde48001122
2024-03-15 15:02:06,130 — main.py:73 -     get_qna_response() — INFO — [] - Starting to serve request:answer_id:e355ca70-e2ae-11ee-8eca-acde48001122
2024-03-15 15:02:06,130 — main.py:54 -     validate_request() — WARNING — [] - answer_id:None:Defaulting Model
2024-03-15 15:02:06,131 — main.py:115 -     get_qna_response() — ERROR — [] - answer_id:e355ca70-e2ae-11ee-8eca-acde48001122:CustomException: 500 - Issue in initialising doc_retriever: DOC_RETRIEVER value <src.components.doc_retriever.VectorDBRetriever object at 0x7fbaaa2656d0> in config is invalid :Traceback (most recent call last):;  File "/Users/reverma/git/custom-rag-pipeline/src/main.py", line 94, in get_qna_response;    qa_gen.prepare();  File "/Users/reverma/git/custom-rag-pipeline/src/answer_generator.py", line 33, in prepare;    "user_query": user_query,;  File "/Users/reverma/git/custom-rag-pipeline/src/components/search_handler.py", line 22, in get_doc_retriever;    raise CustomException(;src.utils.exceptions.CustomException: CustomException: 500 - Issue in initialising doc_retriever: DOC_RETRIEVER value <src.components.doc_retriever.VectorDBRetriever object at 0x7fbaaa2656d0> in config is invalid;
2024-03-15 15:02:11,113 — main.py:70 -     get_qna_response() — INFO — [] - answer_id:e64e21dc-e2ae-11ee-8eca-acde48001122
2024-03-15 15:02:11,113 — main.py:73 -     get_qna_response() — INFO — [] - Starting to serve request:answer_id:e64e21dc-e2ae-11ee-8eca-acde48001122
2024-03-15 15:02:11,113 — main.py:54 -     validate_request() — WARNING — [] - answer_id:None:Defaulting Model
2024-03-15 15:02:11,114 — main.py:115 -     get_qna_response() — ERROR — [] - answer_id:e64e21dc-e2ae-11ee-8eca-acde48001122:CustomException: 500 - Issue in initialising doc_retriever: DOC_RETRIEVER value <src.components.doc_retriever.VectorDBRetriever object at 0x7fba181a7400> in config is invalid :Traceback (most recent call last):;  File "/Users/reverma/git/custom-rag-pipeline/src/main.py", line 94, in get_qna_response;    qa_gen.prepare();  File "/Users/reverma/git/custom-rag-pipeline/src/answer_generator.py", line 33, in prepare;    "user_query": user_query,;  File "/Users/reverma/git/custom-rag-pipeline/src/components/search_handler.py", line 22, in get_doc_retriever;    raise CustomException(;src.utils.exceptions.CustomException: CustomException: 500 - Issue in initialising doc_retriever: DOC_RETRIEVER value <src.components.doc_retriever.VectorDBRetriever object at 0x7fba181a7400> in config is invalid;
2024-03-15 15:02:45,923 — main.py:70 -     get_qna_response() — INFO — [] - answer_id:fb0dbf42-e2ae-11ee-8eca-acde48001122
2024-03-15 15:02:45,923 — main.py:73 -     get_qna_response() — INFO — [] - Starting to serve request:answer_id:fb0dbf42-e2ae-11ee-8eca-acde48001122
2024-03-15 15:02:45,924 — main.py:54 -     validate_request() — WARNING — [] - answer_id:None:Defaulting Model
2024-03-15 15:03:39,692 — main.py:115 -     get_qna_response() — ERROR — [] - answer_id:fb0dbf42-e2ae-11ee-8eca-acde48001122:CustomException: 500 - Issue in initialising doc_retriever: DOC_RETRIEVER value <src.components.doc_retriever.VectorDBRetriever object at 0x7fba891da550> in config is invalid :Traceback (most recent call last):;  File "/Users/reverma/git/custom-rag-pipeline/src/main.py", line 94, in get_qna_response;    qa_gen.prepare();  File "/Users/reverma/git/custom-rag-pipeline/src/answer_generator.py", line 33, in prepare;    "user_query": user_query,;  File "/Users/reverma/git/custom-rag-pipeline/src/components/search_handler.py", line 22, in get_doc_retriever;    raise CustomException(;src.utils.exceptions.CustomException: CustomException: 500 - Issue in initialising doc_retriever: DOC_RETRIEVER value <src.components.doc_retriever.VectorDBRetriever object at 0x7fba891da550> in config is invalid;
2024-03-15 15:04:01,769 — main.py:70 -     get_qna_response() — INFO — [] - answer_id:2842ec62-e2af-11ee-8eca-acde48001122
2024-03-15 15:04:01,771 — main.py:73 -     get_qna_response() — INFO — [] - Starting to serve request:answer_id:2842ec62-e2af-11ee-8eca-acde48001122
2024-03-15 15:04:01,785 — main.py:54 -     validate_request() — WARNING — [] - answer_id:None:Defaulting Model
2024-03-15 15:19:02,465 — main.py:70 -     get_qna_response() — INFO — [] - answer_id:411e3c76-e2b1-11ee-9dae-acde48001122
2024-03-15 15:19:02,467 — main.py:73 -     get_qna_response() — INFO — [] - Starting to serve request:answer_id:411e3c76-e2b1-11ee-9dae-acde48001122
2024-03-15 15:19:02,469 — main.py:54 -     validate_request() — WARNING — [] - answer_id:None:Defaulting Model
2024-03-15 15:21:41,570 — main.py:115 -     get_qna_response() — ERROR — [] - answer_id:411e3c76-e2b1-11ee-9dae-acde48001122:CustomException: 500 - Issue in initialising doc_retriever: DOC_RETRIEVER value <src.components.doc_retriever.VectorDBRetriever object at 0x7fec38dc1b50> in config is invalid :Traceback (most recent call last):;  File "/Users/reverma/git/custom-rag-pipeline/src/main.py", line 94, in get_qna_response;    qa.prepare();  File "/Users/reverma/git/custom-rag-pipeline/src/answer_generator.py", line 47, in prepare;    self.search_handler.get_doc_retriever();  File "/Users/reverma/git/custom-rag-pipeline/src/components/search_handler.py", line 22, in get_doc_retriever;    raise CustomException(;src.utils.exceptions.CustomException: CustomException: 500 - Issue in initialising doc_retriever: DOC_RETRIEVER value <src.components.doc_retriever.VectorDBRetriever object at 0x7fec38dc1b50> in config is invalid;
2024-03-15 15:26:40,458 — main.py:70 -     get_qna_response() — INFO — [] - answer_id:521a5b6c-e2b2-11ee-8a90-acde48001122
2024-03-15 15:26:40,459 — main.py:73 -     get_qna_response() — INFO — [] - Starting to serve request:answer_id:521a5b6c-e2b2-11ee-8a90-acde48001122
2024-03-15 15:26:40,460 — main.py:54 -     validate_request() — WARNING — [] - answer_id:None:Defaulting Model
